<?xml version='1.0'?>
<sdf version="1.4">
  <model name="ugv">
  

  
        <link name='chassis'>
          <pose>0 0 .115 0 0 0</pose>
          
          <inertial>
            <mass value="23" />
	      <origin xyz="0 0 .180" />
	      <inertia ixx="23.0" ixy="0.0" ixz="0.0"
		iyy="23.0" iyz="0.0"
		izz="23.0" />
	   </inertial>
          
          <collision name='collision'>
            <geometry>
              <box>
                <size>.600 .380 .130</size>
              </box>
            </geometry>
          </collision>

          <visual name='visual'>
            <geometry>
              <box>
                <size>.600 .380 .130</size>
              </box>
            </geometry>
          </visual>
      </link>
      <link name="left_front_wheel">
        <pose>0.3 0.240 0.08 0 1.5707 1.5707</pose>
        <collision name="collision">
          <geometry>
            <cylinder>
              <radius>.08</radius>
              <length>.1</length>
            </cylinder>
          </geometry>
        </collision>
        <visual name="visual">
          <geometry>
            <cylinder>
              <radius>.08</radius>
              <length>.1</length>
            </cylinder>
          </geometry>
        </visual>
      </link>
      
      <link name="left_rear_wheel">
        <pose>-0.3 0.240 0.08 0 1.5707 1.5707</pose>
        <collision name="collision">
          <geometry>
            <cylinder>
              <radius>.08</radius>
              <length>.1</length>
            </cylinder>
          </geometry>
        </collision>
        <visual name="visual">
          <geometry>
            <cylinder>
              <radius>.08</radius>
              <length>.1</length>
            </cylinder>
          </geometry>
        </visual>
      </link>

      <link name="right_front_wheel">
        <pose>0.3 -0.240 0.08 0 1.5707 1.5707</pose>
        <collision name="collision">
          <geometry>
            <cylinder>
              <radius>.08</radius>
              <length>.1</length>
            </cylinder>
          </geometry>
        </collision>
        <visual name="visual">
          <geometry>
            <cylinder>
              <radius>.08</radius>
              <length>.1</length>
            </cylinder>
          </geometry>
        </visual>
      </link>  
      
      <link name="right_rear_wheel">
        <pose>-0.3 -0.240 0.08 0 1.5707 1.5707</pose>
        <collision name="collision">
          <geometry>
            <cylinder>
              <radius>.08</radius>
              <length>.1</length>
            </cylinder>
          </geometry>
        </collision>
        <visual name="visual">
          <geometry>
            <cylinder>
              <radius>.08</radius>
              <length>.1</length>
            </cylinder>
          </geometry>
        </visual>
      </link>  
      
      <joint type="revolute" name="left_front_wheel_hinge">
        <pose>0 0 -0.03 0 0 0</pose>
        <child>left_front_wheel</child>
        <parent>chassis</parent>
        <axis>
          <xyz>0 1 0</xyz>
        </axis>
      </joint>
      
      <joint type="revolute" name="left_rear_wheel_hinge">
        <pose>0 0 -0.03 0 0 0</pose>
        <child>left_rear_wheel</child>
        <parent>chassis</parent>
        <axis>
          <xyz>0 1 0</xyz>
        </axis>
      </joint>

      <joint type="revolute" name="right_front_wheel_hinge">
        <pose>0 0 0.03 0 0 0</pose>
        <child>right_front_wheel</child>
        <parent>chassis</parent>
        <axis>
          <xyz>0 1 0</xyz>
        </axis>
      </joint>
      
      <joint type="revolute" name="right_rear_wheel_hinge">
        <pose>0 0 0.03 0 0 0</pose>
        <child>right_rear_wheel</child>
        <parent>chassis</parent>
        <axis>
          <xyz>0 1 0</xyz>
        </axis>
      </joint>
      

    <plugin name="object_controller" filename="libgazebo_ros_planar_move.so">
      <commandTopic>/ugv/cmd_vel</commandTopic>
      <odometryRate>20.0</odometryRate>
      <robotBaseFrame>chassis</robotBaseFrame>
    </plugin>
  </model>
</sdf>
