<?xml version='1.0'?>
<sdf version='1.7'>
  <model name='scout_mini_4k'>
    <link name='base_link'>
      <inertial>
        <pose>0 0 0 0 -0 0</pose>
        <mass>60</mass>
        <inertia>
          <ixx>2.28864</ixx>
          <ixy>0</ixy>
          <ixz>0</ixz>
          <iyy>5.10398</iyy>
          <iyz>0</iyz>
          <izz>3.43147</izz>
        </inertia>
      </inertial>
      <collision name='base_link_collision'>
        <pose>0 0 0 1.57 -0 1.57</pose>
        <geometry>
          <mesh>
            <scale>1 1 1</scale>
            <uri>model://scout_mini/meshes/scout_mini_base_link2.dae</uri>
          </mesh>
        </geometry>
      </collision>
      <visual name='base_link_visual'>
        <pose>0 0 0 1.57 -0 1.57</pose>
        <geometry>
          <mesh>
            <scale>1 1 1</scale>
            <uri>model://scout_mini/meshes/scout_mini_base_link2.dae</uri>
          </mesh>
        </geometry>
      </visual>
    </link>
    <joint name='front_left_wheel' type='revolute'>
      <pose relative_to='base_link'>0.231976 0.208252 -0.100998 -1.57 0 0</pose>
      <parent>base_link</parent>
      <child>front_left_wheel_link</child>
      <axis>
        <xyz>0 0 -1</xyz>
        <limit>
          <lower>-1e+16</lower>
          <upper>1e+16</upper>
        </limit>
        <dynamics>
          <spring_reference>0</spring_reference>
          <spring_stiffness>0</spring_stiffness>
        </dynamics>
      </axis>
    </joint>
    <link name='front_left_wheel_link'>
      <pose relative_to='front_left_wheel'>0 0 0 0 -0 0</pose>
      <inertial>
        <pose>0 0 0 0 -0 0</pose>
        <mass>3</mass>
        <inertia>
          <ixx>0.7171</ixx>
          <ixy>0</ixy>
          <ixz>0</ixz>
          <iyy>0.7171</iyy>
          <iyz>0</iyz>
          <izz>0.1361</izz>
        </inertia>
      </inertial>
      <collision name='front_left_wheel_link_collision'>
        <pose>0 0 0 0 -0 0</pose>
        <geometry>
          <mesh>
            <scale>1 1 1</scale>
            <uri>model://scout_mini/meshes/wheel.dae</uri>
          </mesh>
        </geometry>
      </collision>
      <visual name='front_left_wheel_link_visual'>
        <pose>0 0 0 0 -0 0</pose>
        <geometry>
          <mesh>
            <scale>1 1 1</scale>
            <uri>model://scout_mini/meshes/wheel.dae</uri>
          </mesh>
        </geometry>
      </visual>
    </link>
    <joint name='front_right_wheel' type='revolute'>
      <pose relative_to='base_link'>0.231976 -0.208252 -0.099998 1.57 -0 0</pose>
      <parent>base_link</parent>
      <child>front_right_wheel_link</child>
      <axis>
        <xyz>0 0 -1</xyz>
        <limit>
          <lower>-1e+16</lower>
          <upper>1e+16</upper>
        </limit>
        <dynamics>
          <spring_reference>0</spring_reference>
          <spring_stiffness>0</spring_stiffness>
        </dynamics>
      </axis>
    </joint>
    <link name='front_right_wheel_link'>
      <pose relative_to='front_right_wheel'>0 0 0 0 -0 0</pose>
      <inertial>
        <pose>0 0 0 0 -0 0</pose>
        <mass>3</mass>
        <inertia>
          <ixx>0.7171</ixx>
          <ixy>0</ixy>
          <ixz>0</ixz>
          <iyy>0.7171</iyy>
          <iyz>0</iyz>
          <izz>0.1361</izz>
        </inertia>
      </inertial>
      <collision name='front_right_wheel_link_collision'>
        <pose>0 0 0 0 -0 0</pose>
        <geometry>
          <mesh>
            <scale>1 1 1</scale>
            <uri>model://scout_mini/meshes/wheel.dae</uri>
          </mesh>
        </geometry>
      </collision>
      <visual name='front_right_wheel_link_visual'>
        <pose>0 0 0 0 -0 0</pose>
        <geometry>
          <mesh>
            <scale>1 1 1</scale>
            <uri>model://scout_mini/meshes/wheel.dae</uri>
          </mesh>
        </geometry>
      </visual>
    </link>
    <joint name='rear_left_wheel' type='revolute'>
      <pose relative_to='base_link'>-0.231976 0.208252 -0.100998 -1.57 0 0</pose>
      <parent>base_link</parent>
      <child>rear_left_wheel_link</child>
      <axis>
        <xyz>0 0 -1</xyz>
        <limit>
          <lower>-1e+16</lower>
          <upper>1e+16</upper>
        </limit>
        <dynamics>
          <spring_reference>0</spring_reference>
          <spring_stiffness>0</spring_stiffness>
        </dynamics>
      </axis>
    </joint>
    <link name='rear_left_wheel_link'>
      <pose relative_to='rear_left_wheel'>0 0 0 0 -0 0</pose>
      <inertial>
        <pose>0 0 0 0 -0 0</pose>
        <mass>3</mass>
        <inertia>
          <ixx>0.7171</ixx>
          <ixy>0</ixy>
          <ixz>0</ixz>
          <iyy>0.7171</iyy>
          <iyz>0</iyz>
          <izz>0.1361</izz>
        </inertia>
      </inertial>
      <collision name='rear_left_wheel_link_collision'>
        <pose>0 0 0 0 -0 0</pose>
        <geometry>
          <mesh>
            <scale>1 1 1</scale>
            <uri>model://scout_mini/meshes/wheel.dae</uri>
          </mesh>
        </geometry>
      </collision>
      <visual name='rear_left_wheel_link_visual'>
        <pose>0 0 0 0 -0 0</pose>
        <geometry>
          <mesh>
            <scale>1 1 1</scale>
            <uri>model://scout_mini/meshes/wheel.dae</uri>
          </mesh>
        </geometry>
      </visual>
    </link>
    <joint name='rear_right_wheel' type='revolute'>
      <pose relative_to='base_link'>-0.231976 -0.208252 -0.099998 1.57 -0 0</pose>
      <parent>base_link</parent>
      <child>rear_right_wheel_link</child>
      <axis>
        <xyz>0 0 -1</xyz>
        <limit>
          <lower>-1e+16</lower>
          <upper>1e+16</upper>
        </limit>
        <dynamics>
          <spring_reference>0</spring_reference>
          <spring_stiffness>0</spring_stiffness>
        </dynamics>
      </axis>
    </joint>
    <link name='rear_right_wheel_link'>
      <pose relative_to='rear_right_wheel'>0 0 0 0 -0 0</pose>
      <inertial>
        <pose>0 0 0 0 -0 0</pose>
        <mass>3</mass>
        <inertia>
          <ixx>0.7171</ixx>
          <ixy>0</ixy>
          <ixz>0</ixz>
          <iyy>0.7171</iyy>
          <iyz>0</iyz>
          <izz>0.1361</izz>
        </inertia>
      </inertial>
      <collision name='rear_right_wheel_link_collision'>
        <pose>0 0 0 0 -0 0</pose>
        <geometry>
          <mesh>
            <scale>1 1 1</scale>
            <uri>model://scout_mini/meshes/wheel.dae</uri>
          </mesh>
        </geometry>
      </collision>
      <visual name='rear_right_wheel_link_visual'>
        <pose>0 0 0 0 -0 0</pose>
        <geometry>
          <mesh>
            <scale>1 1 1</scale>
            <uri>model://scout_mini/meshes/wheel.dae</uri>
          </mesh>
        </geometry>
      </visual>
    </link>


    <include>
      <uri>model://velodyne_VLP16</uri>
      <pose>0 0 0.18 0 0 0</pose>
    </include>
    <joint name="lidar_joint" type="fixed">
      <child>velodyne-VLP16::UGV_lidar_base_link</child>
      <parent>base_link</parent>
    </joint>

     <include>
      <uri>model://RGB_camera_4k_f</uri>
      <name>frontal_camera</name>
      <pose>0.03 -0.005 .1 0 0 0</pose>
    </include>
    <joint name="frontal_camera_joint" type="fixed">
      <child>frontal_camera::link</child>
      <parent>base_link</parent>
    </joint>

    <include>
      <uri>model://RGB_camera_4k_rr</uri>
      <name>right_rear_camera</name>
      <pose>-0.03 0.03 .1 0 0 2.3561</pose>
    </include>
    <joint name="right_rear_camera_joint" type="fixed">
      <child>right_rear_camera::link</child>
      <parent>base_link</parent>
    </joint>

    <include>
      <uri>model://RGB_camera_4k_rl</uri>
      <name>left_rear_camera</name>
      <pose>-0.03 -0.03 .1 0 0 -2.35619</pose>
    </include>
    <joint name="left_rear_camera_joint" type="fixed">
      <child>left_rear_camera::link</child>
      <parent>base_link</parent>
    </joint>

    <include>
      <uri>model://ugv_depth_cam</uri>
      <name>depth_camera</name>
      <pose>0.03 0.005 .1 0 0 0</pose>
    </include>
    <joint name="depth_camera_joint" type="fixed">
      <child>depth_camera::link</child>
      <parent>base_link</parent>
    </joint>

    <static>0</static>
    <plugin name='object_controller' filename='libgazebo_ros_planar_move.so'>
      <commandTopic>/cmd_vel</commandTopic>
      <odometryTopic>/ugv/odom_planar_move</odometryTopic>
      <odometryFrame>UGV_odom_frame</odometryFrame>
      <odometryRate>20.0</odometryRate>
      <robotBaseFrame>UGV_base_footprint_frame</robotBaseFrame>
    </plugin>
  </model>
</sdf>
